Workbook

Sheet car_master
A1: record_id | B1: product_code | C1: brand_name | D1: model_name | E1: trim_variant | F1: fuel_type | G1: engine_cc | H1: ex_showroom_inr | I1: import_cif_inr
A2: 1 | B2: 101 | C2: Mercedes-Benz | D2: A-Class Limousine | E2: A200 | F2: Petrol | G2: 1332 | H2: 4600000 | I2: 3800000
A3: 2 | B3: 102 | C3: Mercedes-Benz | D3: A-Class Limousine | E3: A200d | F3: Diesel | G3: 1950 | H3: 4800000 | I3: 4000000
A4: 3 | B4: 103 | C4: Mercedes-Benz | D4: C-Class | E4: C200 | F4: Petrol | G4: 1999 | H4: 5900000 | I4: 5000000
A5: 4 | B5: 104 | C5: Mercedes-Benz | D5: C-Class | E5: C220d | F5: Diesel | G5: 1993 | H5: 6400000 | I5: 5400000
A6: 5 | B6: 105 | C6: Mercedes-Benz | D6: E-Class | E6: E200 | F6: Petrol | G6: 1999 | H6: 7800000 | I6: 6500000
A7: 6 | B7: 106 | C7: Mercedes-Benz | D7: E-Class | E7: E220d | F7: Diesel | G7: 1950 | H7: 8200000 | I7: 6800000
A8: 7 | B8: 107 | C8: Mercedes-Benz | D8: GLA | E8: 220 | F8: Petrol | G8: 1991 | H8: 5000000 | I8: 4200000
A9: 8 | B9: 108 | C9: Mercedes-Benz | D9: GLA | E9: 220d | F9: Diesel | G9: 1950 | H9: 5300000 | I9: 4400000
A10: 9 | B10: 109 | C10: Mercedes-Benz | D10: GLC | E10: 300 | F10: Petrol | G10: 1999 | H10: 7400000 | I10: 6200000
A11: 10 | B11: 110 | C11: Mercedes-Benz | D11: GLC | E11: 220d | F11: Diesel | G11: 1993 | H11: 7700000 | I11: 6500000
A12: 11 | B12: 111 | C12: Volkswagen | D12: Virtus | E12: Comfortline | F12: Petrol | G12: 999 | H12: 1150000 | I12: 900000
A13: 12 | B13: 112 | C13: Volkswagen | D13: Virtus | E13: Highline | F13: Petrol | G13: 999 | H13: 1350000 | I13: 1050000
A14: 13 | B14: 113 | C14: Volkswagen | D14: Virtus | E14: GT Plus | F14: Petrol | G14: 1498 | H14: 1900000 | I14: 1500000
A15: 14 | B15: 114 | C15: Volkswagen | D15: Taigun | E15: Comfortline | F15: Petrol | G15: 999 | H15: 1200000 | I15: 950000
A16: 15 | B16: 115 | C16: Volkswagen | D16: Taigun | E16: Highline | F16: Petrol | G16: 999 | H16: 1500000 | I16: 1200000
A17: 16 | B17: 116 | C17: Volkswagen | D17: Taigun | E17: GT Plus | F17: Petrol | G17: 1498 | H17: 1950000 | I17: 1550000
A18: 17 | B18: 117 | C18: Volkswagen | D18: Tiguan | E18: Elegance | F18: Petrol | G18: 1984 | H18: 3500000 | I18: 2800000
A19: 18 | B19: 118 | C19: Volkswagen | D19: Tiguan | E19: R-Line | F19: Petrol | G19: 1984 | H19: 3800000 | I19: 3050000
A20: 19 | B20: 119 | C20: Volkswagen | D20: Polo | E20: GT TSI | F20: Petrol | G20: 999 | H20: 1000000 | I20: 780000
A21: 20 | B21: 120 | C21: Volkswagen | D21: Vento | E21: Highline | F21: Petrol | G21: 1598 | H21: 1200000 | I21: 950000
A22: 21 | B22: 121 | C22: BMW | D22: 2 Series Gran Coupe | E22: 220i | F22: Petrol | G22: 1998 | H22: 4500000 | I22: 3600000
... A38: 37 | B38: 137 | C38: Skoda | D38: Kodiaq | E38: L&K | F38: Petrol | G38: 1984 | H38: 3800000 | I38: 3000000

Sheet tax_parameters
A1: scenario | B1: bcd_rate | C1: sws_rate | D1: igst_rate | E1: cess_rate
A2: No_FTA | B2: 0.7 | C2: 0.1 | D2: 0.28 | E2: 0.22
A3: With_FTA | B3: 0.1 | C3: 0.1 | D3: 0.28 | E3: 0.22

Sheet import_cost_model
A1: record_id | B1: product_code | C1: brand_name | D1: model_name | E1: trim_variant | F1: scenario | G1: import_cif_inr | H1: bcd_inr | I1: sws_inr | J1: igst_base_inr | K1: igst_inr | L1: cess_inr | M1: total_tax_inr | N1: landed_cost_inr | O1: fta_savings_inr
A2: 1 | B2: 101 | C2: Mercedes-Benz | D2: A-Class Limousine | E2: A200 | F2: with_FTA | G2: =_xlfn.XLOOKUP($B2,car_master!$B2:$B38,car_master!$I2:$I38) -> 3800000 | H2: =_xlfn.XLOOKUP(B2,car_master!$B2:$B38,car_master!$I2:$I38) * tax_parameters!$B$3 -> 380000 | I2: {=_xlfn.XLOOKUP($B2,$B1:$B38,$H1:$H38 * tax_parameters!$C$3)} -> 38000 | J2: =G2 + H2 + I2 -> 4218000 | K2: {=_xlfn.XLOOKUP($B2, $B2:$B38, $J2:$J38 * 0.28)} -> 1181040 | L2: {=_xlfn.XLOOKUP($B2, $B2:$B38, $J2:$J38 * 0.22)} -> 927960 | M2: =H2 + I2 + K2+ L2 -> 2527000 | N2: =G2 + M2 -> 6327000 | O2: =IF( F2="With_FTA", M2 - SUMIFS($M:$M,$A:$A,$A2,$F:$F,"No_FTA"), "" ) -> 2527000
A3: 2 | B3: 102 | C3: Mercedes-Benz | D3: A-Class Limousine | E3: A200d | F3: with_FTA | G3: =_xlfn.XLOOKUP($B3,car_master!$B3:$B39,car_master!$I3:$I39) -> 4000000 | H3: =_xlfn.XLOOKUP(B3,car_master!$B3:$B39,car_master!$I3:$I39) * tax_parameters!$B$3 -> 400000 | I3: {=_xlfn.XLOOKUP($B3,$B2:$B40,$H2:$H40 * tax_parameters!$C$3)} -> 40000 | J3: =G3 + H3 + I3 -> 4440000 | K3: {=_xlfn.XLOOKUP($B3, $B3:$B40, $J3:$J40 * 0.28)} -> 1243200 | L3: {=_xlfn.XLOOKUP($B3, $B3:$B39, $J3:$J39 * 0.22)} -> 976800 | M3: =H3 + I3 + K3+ L3 -> 2660000 | N3: =G3 + M3 -> 6660000 | O3: =IF( F3="With_FTA", M3 - SUMIFS($M:$M,$A:$A,$A3,$F:$F,"No_FTA"), "" ) -> 2660000
A4: 3 | B4: 103 | C4: Mercedes-Benz | D4: C-Class | E4: C200 | F4: with_FTA | G4: =_xlfn.XLOOKUP($B4,car_master!$B4:$B40,car_master!$I4:$I40) -> 5000000 | H4: =_xlfn.XLOOKUP(B4,car_master!$B4:$B40,car_master!$I4:$I40) * tax_parameters!$B$3 -> 500000 | I4: {=_xlfn.XLOOKUP($B4,$B3:$B41,$H3:$H41 * tax_parameters!$C$3)} -> 50000 | J4: =G4 + H4 + I4 -> 5550000 | K4: {=_xlfn.XLOOKUP($B4, $B4:$B41, $J4:$J41 * 0.28)} -> 1554000 | L4: {=_xlfn.XLOOKUP($B4, $B4:$B40, $J4:$J40 * 0.22)} -> 1221000 | M4: =H4 + I4 + K4+ L4 -> 3325000 | N4: =G4 + M4 -> 8325000 | O4: =IF( F4="With_FTA", M4 - SUMIFS($M:$M,$A:$A,$A4,$F:$F,"No_FTA"), "" ) -> 3325000
A5: 4 | B5: 104 | C5: Mercedes-Benz | D5: C-Class | E5: C220d | F5: with_FTA | G5: =_xlfn.XLOOKUP($B5,car_master!$B5:$B41,car_master!$I5:$I41) -> 5400000 | H5: =_xlfn.XLOOKUP(B5,car_master!$B5:$B41,car_master!$I5:$I41) * tax_parameters!$B$3 -> 540000 | I5: {=_xlfn.XLOOKUP($B5,$B4:$B42,$H4:$H42 * tax_parameters!$C$3)} -> 54000 | J5: =G5 + H5 + I5 -> 5994000 | K5: {=_xlfn.XLOOKUP($B5, $B5:$B42, $J5:$J42 * 0.28)} -> 1678320 | L5: {=_xlfn.XLOOKUP($B5, $B5:$B41, $J5:$J41 * 0.22)} -> 1318680 | M5: =H5 + I5 + K5+ L5 -> 3591000 | N5: =G5 + M5 -> 8991000 | O5: =IF( F5="With_FTA", M5 - SUMIFS($M:$M,$A:$A,$A5,$F:$F,"No_FTA"), "" ) -> 3591000
A6: 5 | B6: 105 | C6: Mercedes-Benz | D6: E-Class | E6: E200 | F6: with_FTA | G6: =_xlfn.XLOOKUP($B6,car_master!$B6:$B42,car_master!$I6:$I42) -> 6500000 | H6: =_xlfn.XLOOKUP(B6,car_master!$B6:$B42,car_master!$I6:$I42) * tax_parameters!$B$3 -> 650000 | I6: {=_xlfn.XLOOKUP($B6,$B5:$B43,$H5:$H43 * tax_parameters!$C$3)} -> 65000 | J6: =G6 + H6 + I6 -> 7215000 | K6: {=_xlfn.XLOOKUP($B6, $B6:$B43, $J6:$J43 * 0.28)} -> 2020200 | L6: {=_xlfn.XLOOKUP($B6, $B6:$B42, $J6:$J42 * 0.22)} -> 1587300 | M6: =H6 + I6 + K6+ L6 -> 4322500 | N6: =G6 + M6 -> 10822500 | O6: =IF( F6="With_FTA", M6 - SUMIFS($M:$M,$A:$A,$A6,$F:$F,"No_FTA"), "" ) -> 4322500
A7: 6 | B7: 106 | C7: Mercedes-Benz | D7: E-Class | E7: E220d | F7: with_FTA | G7: =_xlfn.XLOOKUP($B7,car_master!$B7:$B43,car_master!$I7:$I43) -> 6800000 | H7: =_xlfn.XLOOKUP(B7,car_master!$B7:$B43,car_master!$I7:$I43) * tax_parameters!$B$3 -> 680000 | I7: {=_xlfn.XLOOKUP($B7,$B6:$B44,$H6:$H44 * tax_parameters!$C$3)} -> 68000 | J7: =G7 + H7 + I7 -> 7548000 | K7: {=_xlfn.XLOOKUP($B7, $B7:$B44, $J7:$J44 * 0.28)} -> 2113440 | L7: {=_xlfn.XLOOKUP($B7, $B7:$B43, $J7:$J43 * 0.22)} -> 1660560 | M7: =H7 + I7 + K7+ L7 -> 4522000 | N7: =G7 + M7 -> 11322000 | O7: =IF( F7="With_FTA", M7 - SUMIFS($M:$M,$A:$A,$A7,$F:$F,"No_FTA"), "" ) -> 4522000
A8: 7 | B8: 107 | C8: Mercedes-Benz | D8: GLA | E8: 220 | F8: with_FTA | G8: =_xlfn.XLOOKUP($B8,car_master!$B8:$B44,car_master!$I8:$I44) -> 4200000 | H8: =_xlfn.XLOOKUP(B8,car_master!$B8:$B44,car_master!$I8:$I44) * tax_parameters!$B$3 -> 420000 | I8: {=_xlfn.XLOOKUP($B8,$B7:$B45,$H7:$H45 * tax_parameters!$C$3)} -> 42000 | J8: =G8 + H8 + I8 -> 4662000 | K8: {=_xlfn.XLOOKUP($B8, $B8:$B45, $J8:$J45 * 0.28)} -> 1305360 | L8: {=_xlfn.XLOOKUP($B8, $B8:$B44, $J8:$J44 * 0.22)} -> 1025640 | M8: =H8 + I8 + K8+ L8 -> 2793000 | N8: =G8 + M8 -> 6993000 | O8: =IF( F8="With_FTA", M8 - SUMIFS($M:$M,$A:$A,$A8,$F:$F,"No_FTA"), "" ) -> 2793000
A9: 8 | B9: 108 | C9: Mercedes-Benz | D9: GLA | E9: 220d | F9: with_FTA | G9: =_xlfn.XLOOKUP($B9,car_master!$B9:$B45,car_master!$I9:$I45) -> 4400000 | H9: =_xlfn.XLOOKUP(B9,car_master!$B9:$B45,car_master!$I9:$I45) * tax_parameters!$B$3 -> 440000 | I9: {=_xlfn.XLOOKUP($B9,$B8:$B46,$H8:$H46 * tax_parameters!$C$3)} -> 44000 | J9: =G9 + H9 + I9 -> 4884000 | K9: {=_xlfn.XLOOKUP($B9, $B9:$B46, $J9:$J46 * 0.28)} -> 1367520 | L9: {=_xlfn.XLOOKUP($B9, $B9:$B45, $J9:$J45 * 0.22)} -> 1074480 | M9: =H9 + I9 + K9+ L9 -> 2926000 | N9: =G9 + M9 -> 7326000 | O9: =IF( F9="With_FTA", M9 - SUMIFS($M:$M,$A:$A,$A9,$F:$F,"No_FTA"), "" ) -> 2926000
A10: 9 | B10: 109 | C10: Mercedes-Benz | D10: GLC | E10: 300 | F10: with_FTA | G10: =_xlfn.XLOOKUP($B10,car_master!$B10:$B46,car_master!$I10:$I46) -> 6200000 | H10: =_xlfn.XLOOKUP(B10,car_master!$B10:$B46,car_master!$I10:$I46) * tax_parameters!$B$3 -> 620000 | I10: {=_xlfn.XLOOKUP($B10,$B9:$B47,$H9:$H47 * tax_parameters!$C$3)} -> 62000 | J10: =G10 + H10 + I10 -> 6882000 | K10: {=_xlfn.XLOOKUP($B10, $B10:$B47, $J10:$J47 * 0.28)} -> 1926960 | L10: {=_xlfn.XLOOKUP($B10, $B10:$B46, $J10:$J46 * 0.22)} -> 1514040 | M10: =H10 + I10 + K10+ L10 -> 4123000 | N10: =G10 + M10 -> 10323000 | O10: =IF( F10="With_FTA", M10 - SUMIFS($M:$M,$A:$A,$A10,$F:$F,"No_FTA"), "" ) -> 4123000
A11: 10 | B11: 110 | C11: Mercedes-Benz | D11: GLC | E11: 220d | F11: with_FTA | G11: =_xlfn.XLOOKUP($B11,car_master!$B11:$B47,car_master!$I11:$I47) -> 6500000 | H11: =_xlfn.XLOOKUP(B11,car_master!$B11:$B47,car_master!$I11:$I47) * tax_parameters!$B$3 -> 650000 | I11: {=_xlfn.XLOOKUP($B11,$B10:$B48,$H10:$H48 * tax_parameters!$C$3)} -> 65000 | J11: =G11 + H11 + I11 -> 7215000 | K11: {=_xlfn.XLOOKUP($B11, $B11:$B48, $J11:$J48 * 0.28)} -> 2020200 | L11: {=_xlfn.XLOOKUP($B11, $B11:$B47, $J11:$J47 * 0.22)} -> 1587300 | M11: =H11 + I11 + K11+ L11 -> 4322500 | N11: =G11 + M11 -> 10822500 | O11: =IF( F11="With_FTA", M11 - SUMIFS($M:$M,$A:$A,$A11,$F:$F,"No_FTA"), "" ) -> 4322500
A12: 11 | B12: 111 | C12: Volkswagen | D12: Virtus | E12: Comfortline | F12: with_FTA | G12: =_xlfn.XLOOKUP($B12,car_master!$B12:$B48,car_master!$I12:$I48) -> 900000 | H12: =_xlfn.XLOOKUP(B12,car_master!$B12:$B48,car_master!$I12:$I48) * tax_parameters!$B$3 -> 90000 | I12: {=_xlfn.XLOOKUP($B12,$B11:$B49,$H11:$H49 * tax_parameters!$C$3)} -> 9000 | J12: =G12 + H12 + I12 -> 999000 | K12: {=_xlfn.XLOOKUP($B12, $B12:$B49, $J12:$J49 * 0.28)} -> 279720 | L12: {=_xlfn.XLOOKUP($B12, $B12:$B48, $J12:$J48 * 0.22)} -> 219780 | M12: =H12 + I12 + K12+ L12 -> 598500 | N12: =G12 + M12 -> 1498500 | O12: =IF( F12="With_FTA", M12 - SUMIFS($M:$M,$A:$A,$A12,$F:$F,"No_FTA"), "" ) -> 598500
A13: 12 | B13: 112 | C13: Volkswagen | D13: Virtus | E13: Highline | F13: with_FTA | G13: =_xlfn.XLOOKUP($B13,car_master!$B13:$B49,car_master!$I13:$I49) -> 1050000 | H13: =_xlfn.XLOOKUP(B13,car_master!$B13:$B49,car_master!$I13:$I49) * tax_parameters!$B$3 -> 105000 | I13: {=_xlfn.XLOOKUP($B13,$B12:$B50,$H12:$H50 * tax_parameters!$C$3)} -> 10500 | J13: =G13 + H13 + I13 -> 1165500 | K13: {=_xlfn.XLOOKUP($B13, $B13:$B50, $J13:$J50 * 0.28)} -> 326340 | L13: {=_xlfn.XLOOKUP($B13, $B13:$B49, $J13:$J49 * 0.22)} -> 256410 | M13: =H13 + I13 + K13+ L13 -> 698250 | N13: =G13 + M13 -> 1748250 | O13: =IF( F13="With_FTA", M13 - SUMIFS($M:$M,$A:$A,$A13,$F:$F,"No_FTA"), "" ) -> 698250
A14: 13 | B14: 113 | C14: Volkswagen | D14: Virtus | E14: GT Plus | F14: with_FTA | G14: =_xlfn.XLOOKUP($B14,car_master!$B14:$B50,car_master!$I14:$I50) -> 1500000 | H14: =_xlfn.XLOOKUP(B14,car_master!$B14:$B50,car_master!$I14:$I50) * tax_parameters!$B$3 -> 150000 | I14: {=_xlfn.XLOOKUP($B14,$B13:$B51,$H13:$H51 * tax_parameters!$C$3)} -> 15000 | J14: =G14 + H14 + I14 -> 1665000 | K14: {=_xlfn.XLOOKUP($B14, $B14:$B51, $J14:$J51 * 0.28)} -> 466200 | L14: {=_xlfn.XLOOKUP($B14, $B14:$B50, $J14:$J50 * 0.22)} -> 366300 | M14: =H14 + I14 + K14+ L14 -> 997500 | N14: =G14 + M14 -> 2497500 | O14: =IF( F14="With_FTA", M14 - SUMIFS($M:$M,$A:$A,$A14,$F:$F,"No_FTA"), "" ) -> 997500
A15: 14 | B15: 114 | C15: Volkswagen | D15: Taigun | E15: Comfortline | F15: with_FTA | G15: =_xlfn.XLOOKUP($B15,car_master!$B15:$B51,car_master!$I15:$I51) -> 950000 | H15: =_xlfn.XLOOKUP(B15,car_master!$B15:$B51,car_master!$I15:$I51) * tax_parameters!$B$3 -> 95000 | I15: {=_xlfn.XLOOKUP($B15,$B14:$B52,$H14:$H52 * tax_parameters!$C$3)} -> 9500 | J15: =G15 + H15 + I15 -> 1054500 | K15: {=_xlfn.XLOOKUP($B15, $B15:$B52, $J15:$J52 * 0.28)} -> 295260 | L15: {=_xlfn.XLOOKUP($B15, $B15:$B51, $J15:$J51 * 0.22)} -> 231990 | M15: =H15 + I15 + K15+ L15 -> 631750 | N15: =G15 + M15 -> 1581750 | O15: =IF( F15="With_FTA", M15 - SUMIFS($M:$M,$A:$A,$A15,$F:$F,"No_FTA"), "" ) -> 631750
A16: 15 | B16: 115 | C16: Volkswagen | D16: Taigun | E16: Highline | F16: with_FTA | G16: =_xlfn.XLOOKUP($B16,car_master!$B16:$B52,car_master!$I16:$I52) -> 1200000 | H16: =_xlfn.XLOOKUP(B16,car_master!$B16:$B52,car_master!$I16:$I52) * tax_parameters!$B$3 -> 120000 | I16: {=_xlfn.XLOOKUP($B16,$B15:$B53,$H15:$H53 * tax_parameters!$C$3)} -> 12000 | J16: =G16 + H16 + I16 -> 1332000 | K16: {=_xlfn.XLOOKUP($B16, $B16:$B53, $J16:$J53 * 0.28)} -> 372960 | L16: {=_xlfn.XLOOKUP($B16, $B16:$B52, $J16:$J52 * 0.22)} -> 293040 | M16: =H16 + I16 + K16+ L16 -> 798000 | N16: =G16 + M16 -> 1998000 | O16: =IF( F16="With_FTA", M16 - SUMIFS($M:$M,$A:$A,$A16,$F:$F,"No_FTA"), "" ) -> 798000
A17: 16 | B17: 116 | C17: Volkswagen | D17: Taigun | E17: GT Plus | F17: with_FTA | G17: =_xlfn.XLOOKUP($B17,car_master!$B17:$B53,car_master!$I17:$I53) -> 1550000 | H17: =_xlfn.XLOOKUP(B17,car_master!$B17:$B53,car_master!$I17:$I53) * tax_parameters!$B$3 -> 155000 | I17: {=_xlfn.XLOOKUP($B17,$B16:$B54,$H16:$H54 * tax_parameters!$C$3)} -> 15500 | J17: =G17 + H17 + I17 -> 1720500 | K17: {=_xlfn.XLOOKUP($B17, $B17:$B54, $J17:$J54 * 0.28)} -> 481740 | L17: {=_xlfn.XLOOKUP($B17, $B17:$B53, $J17:$J53 * 0.22)} -> 378510 | M17: =H17 + I17 + K17+ L17 -> 1030750 | N17: =G17 + M17 -> 2580750 | O17: =IF( F17="With_FTA", M17 - SUMIFS($M:$M,$A:$A,$A17,$F:$F,"No_FTA"), "" ) -> 1030750
A18: 17 | B18: 117 | C18: Volkswagen | D18: Tiguan | E18: Elegance | F18: with_FTA | G18: =_xlfn.XLOOKUP($B18,car_master!$B18:$B54,car_master!$I18:$I54) -> 2800000 | H18: =_xlfn.XLOOKUP(B18,car_master!$B18:$B54,car_master!$I18:$I54) * tax_parameters!$B$3 -> 280000 | I18: {=_xlfn.XLOOKUP($B18,$B17:$B55,$H17:$H55 * tax_parameters!$C$3)} -> 28000 | J18: =G18 + H18 + I18 -> 3108000 | K18: {=_xlfn.XLOOKUP($B18, $B18:$B55, $J18:$J55 * 0.28)} -> 870240 | L18: {=_xlfn.XLOOKUP($B18, $B18:$B54, $J18:$J54 * 0.22)} -> 683760 | M18: =H18 + I18 + K18+ L18 -> 1862000 | N18: =G18 + M18 -> 4662000 | O18: =IF( F18="With_FTA", M18 - SUMIFS($M:$M,$A:$A,$A18,$F:$F,"No_FTA"), "" ) -> 1862000
A19: 18 | B19: 118 | C19: Volkswagen | D19: Tiguan | E19: R-Line | F19: with_FTA | G19: =_xlfn.XLOOKUP($B19,car_master!$B19:$B55,car_master!$I19:$I55) -> 3050000 | H19: =_xlfn.XLOOKUP(B19,car_master!$B19:$B55,car_master!$I19:$I55) * tax_parameters!$B$3 -> 305000 | I19: {=_xlfn.XLOOKUP($B19,$B18:$B56,$H18:$H56 * tax_parameters!$C$3)} -> 30500 | J19: =G19 + H19 + I19 -> 3385500 | K19: {=_xlfn.XLOOKUP($B19, $B19:$B56, $J19:$J56 * 0.28)} -> 947940 | L19: {=_xlfn.XLOOKUP($B19, $B19:$B55, $J19:$J55 * 0.22)} -> 744810 | M19: =H19 + I19 + K19+ L19 -> 2028250 | N19: =G19 + M19 -> 5078250 | O19: =IF( F19="With_FTA", M19 - SUMIFS($M:$M,$A:$A,$A19,$F:$F,"No_FTA"), "" ) -> 2028250
A20: 19 | B20: 119 | C20: Volkswagen | D20: Polo | E20: GT TSI | F20: with_FTA | G20: =_xlfn.XLOOKUP($B20,car_master!$B20:$B56,car_master!$I20:$I56) -> 780000 | H20: =_xlfn.XLOOKUP(B20,car_master!$B20:$B56,car_master!$I20:$I56) * tax_parameters!$B$3 -> 78000 | I20: {=_xlfn.XLOOKUP($B20,$B19:$B57,$H19:$H57 * tax_parameters!$C$3)} -> 7800 | J20: =G20 + H20 + I20 -> 865800 | K20: {=_xlfn.XLOOKUP($B20, $B20:$B57, $J20:$J57 * 0.28)} -> 242424 | L20: {=_xlfn.XLOOKUP($B20, $B20:$B56, $J20:$J56 * 0.22)} -> 190476 | M20: =H20 + I20 + K20+ L20 -> 518700 | N20: =G20 + M20 -> 1298700 | O20: =IF( F20="With_FTA", M20 - SUMIFS($M:$M,$A:$A,$A20,$F:$F,"No_FTA"), "" ) -> 518700
A21: 20 | B21: 120 | C21: Volkswagen | D21: Vento | E21: Highline | F21: with_FTA | G21: =_xlfn.XLOOKUP($B21,car_master!$B21:$B57,car_master!$I21:$I57) -> 950000 | H21: =_xlfn.XLOOKUP(B21,car_master!$B21:$B57,car_master!$I21:$I57) * tax_parameters!$B$3 -> 95000 | I21: {=_xlfn.XLOOKUP($B21,$B20:$B58,$H20:$H58 * tax_parameters!$C$3)} -> 9500 | J21: =G21 + H21 + I21 -> 1054500 | K21: {=_xlfn.XLOOKUP($B21, $B21:$B58, $J21:$J58 * 0.28)} -> 295260 | L21: {=_xlfn.XLOOKUP($B21, $B21:$B57, $J21:$J57 * 0.22)} -> 231990 | M21: =H21 + I21 + K21+ L21 -> 631750 | N21: =G21 + M21 -> 1581750 | O21: =IF( F21="With_FTA", M21 - SUMIFS($M:$M,$A:$A,$A21,$F:$F,"No_FTA"), "" ) -> 631750
A22: 21 | B22: 121 | C22: BMW | D22: 2 Series Gran Coupe | E22: 220i | F22: with_FTA | G22: =_xlfn.XLOOKUP($B22,car_master!$B22:$B58,car_master!$I22:$I58) -> 3600000 | H22: =_xlfn.XLOOKUP(B22,car_master!$B22:$B58,car_master!$I22:$I58) * tax_parameters!$B$3 -> 360000 | I22: {=_xlfn.XLOOKUP($B22,$B21:$B59,$H21:$H59 * tax_parameters!$C$3)} -> 36000 | J22: =G22 + H22 + I22 -> 3996000 | K22: {=_xlfn.XLOOKUP($B22, $B22:$B59, $J22:$J59 * 0.28)} -> 1118880 | L22: {=_xlfn.XLOOKUP($B22, $B22:$B58, $J22:$J58 * 0.22)} -> 879120 | M22: =H22 + I22 + K22+ L22 -> 2394000 | N22: =G22 + M22 -> 5994000 | O22: =IF( F22="With_FTA", M22 - SUMIFS($M:$M,$A:$A,$A22,$F:$F,"No_FTA"), "" ) -> 2394000
... A38: 37 | B38: 137 | C38: Skoda | D38: Kodiaq | E38: L&K | F38: with_FTA | G38: =_xlfn.XLOOKUP($B38,car_master!$B38:$B74,car_master!$I38:$I74) -> 3000000 | H38: =_xlfn.XLOOKUP(B38,car_master!$B38:$B74,car_master!$I38:$I74) * tax_parameters!$B$3 -> 300000 | I38: {=_xlfn.XLOOKUP($B38,$B37:$B75,$H37:$H75 * tax_parameters!$C$3)} -> 30000 | J38: =G38 + H38 + I38 -> 3330000 | K38: {=_xlfn.XLOOKUP($B38, $B38:$B75, $J38:$J75 * 0.28)} -> 932400 | L38: {=_xlfn.XLOOKUP($B38, $B38:$B74, $J38:$J74 * 0.22)} -> 732600 | M38: =H38 + I38 + K38+ L38 -> 1995000 | N38: =G38 + M38 -> 4995000 | O38: =IF( F38="With_FTA", M38 - SUMIFS($M:$M,$A:$A,$A38,$F:$F,"No_FTA"), "" ) -> 1995000
O39: =IF( F40="with_FTA", SUMIFS( import_cost_model!L:L, import_cost_model!A:A, A40, import_cost_model!E:E, "no_FTA" ) - M40, "" )
A40: 38 | B40: 138 | C40: Mercedes-Benz | D40: A-Class Limousine | E40: A200 | F40: no_FTA | G40: =_xlfn.XLOOKUP($B2,car_master!$B2:$B38,car_master!$I2:$I38) -> 3800000 | H40: =_xlfn.XLOOKUP(B2,car_master!$B2:$B38,car_master!$I2:$I38) * tax_parameters!$B$2 -> 2660000 | I40: {=_xlfn.XLOOKUP($B40,$B$40:$B$76,$H$40:$H$76 * tax_parameters!$C$2)} -> 266000 | J40: =G40 + H40 + I40 -> 6726000 | K40: {=_xlfn.XLOOKUP($B40,$B40:$B76,$J40:$J76 * tax_parameters!$D$2)} -> 1883280 | L40: {=_xlfn.XLOOKUP($B40, $B40:$B76, $J40:$J76 * 0.22)} -> 1479720 | M40: =H40 + I40 + K40+ L40 -> 6289000 | N40: =G40 + M40 -> 10089000 | O40: =IF( F41="with_FTA", SUMIFS( import_cost_model!L:L, import_cost_model!A:A, A41, import_cost_model!E:E, "no_FTA" ) - M41, "" )
A41: 39 | B41: 139 | C41: Mercedes-Benz | D41: A-Class Limousine | E41: A200d | F41: no_FTA | G41: =_xlfn.XLOOKUP($B3,car_master!$B3:$B39,car_master!$I3:$I39) -> 4000000 | H41: =_xlfn.XLOOKUP(B3,car_master!$B3:$B39,car_master!$I3:$I39) * tax_parameters!$B$2 -> 2800000 | I41: {=_xlfn.XLOOKUP($B41,$B$40:$B$76,$H$40:$H$76 * tax_parameters!$C$2)} -> 280000 | J41: =G41 + H41 + I41 -> 7080000 | K41: {=_xlfn.XLOOKUP($B41,$B41:$B77,$J41:$J77 * tax_parameters!$D$2)} -> 1982400 | L41: {=_xlfn.XLOOKUP($B41, $B41:$B77, $J41:$J77 * 0.22)} -> 1557600 | M41: =H41 + I41 + K41+ L41 -> 6620000 | N41: =G41 + M41 -> 10620000 | O41: =IF( F42="with_FTA", SUMIFS( import_cost_model!L:L, import_cost_model!A:A, A42, import_cost_model!E:E, "no_FTA" ) - M42, "" )
A42: 40 | B42: 140 | C42: Mercedes-Benz | D42: C-Class | E42: C200 | F42: no_FTA | G42: =_xlfn.XLOOKUP($B4,car_master!$B4:$B40,car_master!$I4:$I40) -> 5000000 | H42: =_xlfn.XLOOKUP(B4,car_master!$B4:$B40,car_master!$I4:$I40) * tax_parameters!$B$2 -> 3500000 | I42: {=_xlfn.XLOOKUP($B42,$B$40:$B$76,$H$40:$H$76 * tax_parameters!$C$2)} -> 350000 | J42: =G42 + H42 + I42 -> 8850000 | K42: {=_xlfn.XLOOKUP($B42,$B42:$B78,$J42:$J78 * tax_parameters!$D$2)} -> 2478000 | L42: {=_xlfn.XLOOKUP($B42, $B42:$B78, $J42:$J78 * 0.22)} -> 1947000 | M42: =H42 + I42 + K42+ L42 -> 8275000 | N42: =G42 + M42 -> 13275000 | O42: =IF( F43="with_FTA", SUMIFS( import_cost_model!L:L, import_cost_model!A:A, A43, import_cost_model!E:E, "no_FTA" ) - M43, "" )
A43: 41 | B43: 141 | C43: Mercedes-Benz | D43: C-Class | E43: C220d | F43: no_FTA | G43: =_xlfn.XLOOKUP($B5,car_master!$B5:$B41,car_master!$I5:$I41) -> 5400000 | H43: =_xlfn.XLOOKUP(B5,car_master!$B5:$B41,car_master!$I5:$I41) * tax_parameters!$B$2 -> 3780000 | I43: {=_xlfn.XLOOKUP($B43,$B$40:$B$76,$H$40:$H$76 * tax_parameters!$C$2)} -> 378000 | J43: =G43 + H43 + I43 -> 9558000 | K43: {=_xlfn.XLOOKUP($B43,$B43:$B79,$J43:$J79 * tax_parameters!$D$2)} -> 2676240 | L43: {=_xlfn.XLOOKUP($B43, $B43:$B79, $J43:$J79 * 0.22)} -> 2102760 | M43: =H43 + I43 + K43+ L43 -> 8937000 | N43: =G43 + M43 -> 14337000 | O43: =IF( F44="with_FTA", SUMIFS( import_cost_model!L:L, import_cost_model!A:A, A44, import_cost_model!E:E, "no_FTA" ) - M44, "" )
A44: 42 | B44: 142 | C44: Mercedes-Benz | D44: E-Class | E44: E200 | F44: no_FTA | G44: =_xlfn.XLOOKUP($B6,car_master!$B6:$B42,car_master!$I6:$I42) -> 6500000 | H44: =_xlfn.XLOOKUP(B6,car_master!$B6:$B42,car_master!$I6:$I42) * tax_parameters!$B$2 -> 4550000 | I44: {=_xlfn.XLOOKUP($B44,$B$40:$B$76,$H$40:$H$76 * tax_parameters!$C$2)} -> 455000 | J44: =G44 + H44 + I44 -> 11505000 | K44: {=_xlfn.XLOOKUP($B44,$B44:$B80,$J44:$J80 * tax_parameters!$D$2)} -> 3221400 | L44: {=_xlfn.XLOOKUP($B44, $B44:$B80, $J44:$J80 * 0.22)} -> 2531100 | M44: =H44 + I44 + K44+ L44 -> 10757500 | N44: =G44 + M44 -> 17257500 | O44: =IF( F45="with_FTA", SUMIFS( import_cost_model!L:L, import_cost_model!A:A, A45, import_cost_model!E:E, "no_FTA" ) - M45, "" )
A45: 43 | B45: 143 | C45: Mercedes-Benz | D45: E-Class | E45: E220d | F45: no_FTA | G45: =_xlfn.XLOOKUP($B7,car_master!$B7:$B43,car_master!$I7:$I43) -> 6800000 | H45: =_xlfn.XLOOKUP(B7,car_master!$B7:$B43,car_master!$I7:$I43) * tax_parameters!$B$2 -> 4760000 | I45: {=_xlfn.XLOOKUP($B45,$B$40:$B$76,$H$40:$H$76 * tax_parameters!$C$2)} -> 476000 | J45: =G45 + H45 + I45 -> 12036000 | K45: {=_xlfn.XLOOKUP($B45,$B45:$B81,$J45:$J81 * tax_parameters!$D$2)} -> 3370080 | L45: {=_xlfn.XLOOKUP($B45, $B45:$B81, $J45:$J81 * 0.22)} -> 2647920 | M45: =H45 + I45 + K45+ L45 -> 11254000 | N45: =G45 + M45 -> 18054000 | O45: =IF( F46="with_FTA", SUMIFS( import_cost_model!L:L, import_cost_model!A:A, A46, import_cost_model!E:E, "no_FTA" ) - M46, "" )
A46: 44 | B46: 144 | C46: Mercedes-Benz | D46: GLA | E46: 220 | F46: no_FTA | G46: =_xlfn.XLOOKUP($B8,car_master!$B8:$B44,car_master!$I8:$I44) -> 4200000 | H46: =_xlfn.XLOOKUP(B8,car_master!$B8:$B44,car_master!$I8:$I44) * tax_parameters!$B$2 -> 2940000 | I46: {=_xlfn.XLOOKUP($B46,$B$40:$B$76,$H$40:$H$76 * tax_parameters!$C$2)} -> 294000 | J46: =G46 + H46 + I46 -> 7434000 | K46: {=_xlfn.XLOOKUP($B46,$B46:$B82,$J46:$J82 * tax_parameters!$D$2)} -> 2081520 | L46: {=_xlfn.XLOOKUP($B46, $B46:$B82, $J46:$J82 * 0.22)} -> 1635480 | M46: =H46 + I46 + K46+ L46 -> 6951000 | N46: =G46 + M46 -> 11151000 | O46: =IF( F47="with_FTA", SUMIFS( import_cost_model!L:L, import_cost_model!A:A, A47, import_cost_model!E:E, "no_FTA" ) - M47, "" )
A47: 45 | B47: 145 | C47: Mercedes-Benz | D47: GLA | E47: 220d | F47: no_FTA | G47: =_xlfn.XLOOKUP($B9,car_master!$B9:$B45,car_master!$I9:$I45) -> 4400000 | H47: =_xlfn.XLOOKUP(B9,car_master!$B9:$B45,car_master!$I9:$I45) * tax_parameters!$B$2 -> 3080000 | I47: {=_xlfn.XLOOKUP($B47,$B$40:$B$76,$H$40:$H$76 * tax_parameters!$C$2)} -> 308000 | J47: =G47 + H47 + I47 -> 7788000 | K47: {=_xlfn.XLOOKUP($B47,$B47:$B83,$J47:$J83 * tax_parameters!$D$2)} -> 2180640 | L47: {=_xlfn.XLOOKUP($B47, $B47:$B83, $J47:$J83 * 0.22)} -> 1713360 | M47: =H47 + I47 + K47+ L47 -> 7282000 | N47: =G47 + M47 -> 11682000 | O47: =IF( F48="with_FTA", SUMIFS( import_cost_model!L:L, import_cost_model!A:A, A48, import_cost_model!E:E, "no_FTA" ) - M48, "" )
A48: 46 | B48: 146 | C48: Mercedes-Benz | D48: GLC | E48: 300 | F48: no_FTA | G48: =_xlfn.XLOOKUP($B10,car_master!$B10:$B46,car_master!$I10:$I46) -> 6200000 | H48: =_xlfn.XLOOKUP(B10,car_master!$B10:$B46,car_master!$I10:$I46) * tax_parameters!$B$2 -> 4340000 | I48: {=_xlfn.XLOOKUP($B48,$B$40:$B$76,$H$40:$H$76 * tax_parameters!$C$2)} -> 434000 | J48: =G48 + H48 + I48 -> 10974000 | K48: {=_xlfn.XLOOKUP($B48,$B48:$B84,$J48:$J84 * tax_parameters!$D$2)} -> 3072720 | L48: {=_xlfn.XLOOKUP($B48, $B48:$B84, $J48:$J84 * 0.22)} -> 2414280 | M48: =H48 + I48 + K48+ L48 -> 10261000 | N48: =G48 + M48 -> 16461000 | O48: =IF( F49="with_FTA", SUMIFS( import_cost_model!L:L, import_cost_model!A:A, A49, import_cost_model!E:E, "no_FTA" ) - M49, "" )
A49: 47 | B49: 147 | C49: Mercedes-Benz | D49: GLC | E49: 220d | F49: no_FTA | G49: =_xlfn.XLOOKUP($B11,car_master!$B11:$B47,car_master!$I11:$I47) -> 6500000 | H49: =_xlfn.XLOOKUP(B11,car_master!$B11:$B47,car_master!$I11:$I47) * tax_parameters!$B$2 -> 4550000 | I49: {=_xlfn.XLOOKUP($B49,$B$40:$B$76,$H$40:$H$76 * tax_parameters!$C$2)} -> 455000 | J49: =G49 + H49 + I49 -> 11505000 | K49: {=_xlfn.XLOOKUP($B49,$B49:$B85,$J49:$J85 * tax_parameters!$D$2)} -> 3221400 | L49: {=_xlfn.XLOOKUP($B49, $B49:$B85, $J49:$J85 * 0.22)} -> 2531100 | M49: =H49 + I49 + K49+ L49 -> 10757500 | N49: =G49 + M49 -> 17257500 | O49: =IF( F50="with_FTA", SUMIFS( import_cost_model!L:L, import_cost_model!A:A, A50, import_cost_model!E:E, "no_FTA" ) - M50, "" )
A50: 48 | B50: 148 | C50: Volkswagen | D50: Virtus | E50: Comfortline | F50: no_FTA | G50: =_xlfn.XLOOKUP($B12,car_master!$B12:$B48,car_master!$I12:$I48) -> 900000 | H50: =_xlfn.XLOOKUP(B12,car_master!$B12:$B48,car_master!$I12:$I48) * tax_parameters!$B$2 -> 630000 | I50: {=_xlfn.XLOOKUP($B50,$B$40:$B$76,$H$40:$H$76 * tax_parameters!$C$2)} -> 63000 | J50: =G50 + H50 + I50 -> 1593000 | K50: {=_xlfn.XLOOKUP($B50,$B50:$B86,$J50:$J86 * tax_parameters!$D$2)} -> 446040 | L50: {=_xlfn.XLOOKUP($B50, $B50:$B86, $J50:$J86 * 0.22)} -> 350460 | M50: =H50 + I50 + K50+ L50 -> 1489500 | N50: =G50 + M50 -> 2389500 | O50: =IF( F51="with_FTA", SUMIFS( import_cost_model!L:L, import_cost_model!A:A, A51, import_cost_model!E:E, "no_FTA" ) - M51, "" )
A51: 49 | B51: 149 | C51: Volkswagen | D51: Virtus | E51: Highline | F51: no_FTA | G51: =_xlfn.XLOOKUP($B13,car_master!$B13:$B49,car_master!$I13:$I49) -> 1050000 | H51: =_xlfn.XLOOKUP(B13,car_master!$B13:$B49,car_master!$I13:$I49) * tax_parameters!$B$2 -> 735000 | I51: {=_xlfn.XLOOKUP($B51,$B$40:$B$76,$H$40:$H$76 * tax_parameters!$C$2)} -> 73500 | J51: =G51 + H51 + I51 -> 1858500 | K51: {=_xlfn.XLOOKUP($B51,$B51:$B87,$J51:$J87 * tax_parameters!$D$2)} -> 520380 | L51: {=_xlfn.XLOOKUP($B51, $B51:$B87, $J51:$J87 * 0.22)} -> 408870 | M51: =H51 + I51 + K51+ L51 -> 1737750 | N51: =G51 + M51 -> 2787750 | O51: =IF( F52="with_FTA", SUMIFS( import_cost_model!L:L, import_cost_model!A:A, A52, import_cost_model!E:E, "no_FTA" ) - M52, "" )
A52: 50 | B52: 150 | C52: Volkswagen | D52: Virtus | E52: GT Plus | F52: no_FTA | G52: =_xlfn.XLOOKUP($B14,car_master!$B14:$B50,car_master!$I14:$I50) -> 1500000 | H52: =_xlfn.XLOOKUP(B14,car_master!$B14:$B50,car_master!$I14:$I50) * tax_parameters!$B$2 -> 1050000 | I52: {=_xlfn.XLOOKUP($B52,$B$40:$B$76,$H$40:$H$76 * tax_parameters!$C$2)} -> 105000 | J52: =G52 + H52 + I52 -> 2655000 | K52: {=_xlfn.XLOOKUP($B52,$B52:$B88,$J52:$J88 * tax_parameters!$D$2)} -> 743400 | L52: {=_xlfn.XLOOKUP($B52, $B52:$B88, $J52:$J88 * 0.22)} -> 584100 | M52: =H52 + I52 + K52+ L52 -> 2482500 | N52: =G52 + M52 -> 3982500 | O52: =IF( F53="with_FTA", SUMIFS( import_cost_model!L:L, import_cost_model!A:A, A53, import_cost_model!E:E, "no_FTA" ) - M53, "" )
A53: 51 | B53: 151 | C53: Volkswagen | D53: Taigun | E53: Comfortline | F53: no_FTA | G53: =_xlfn.XLOOKUP($B15,car_master!$B15:$B51,car_master!$I15:$I51) -> 950000 | H53: =_xlfn.XLOOKUP(B15,car_master!$B15:$B51,car_master!$I15:$I51) * tax_parameters!$B$2 -> 665000 | I53: {=_xlfn.XLOOKUP($B53,$B$40:$B$76,$H$40:$H$76 * tax_parameters!$C$2)} -> 66500 | J53: =G53 + H53 + I53 -> 1681500 | K53: {=_xlfn.XLOOKUP($B53,$B53:$B89,$J53:$J89 * tax_parameters!$D$2)} -> 470820 | L53: {=_xlfn.XLOOKUP($B53, $B53:$B89, $J53:$J89 * 0.22)} -> 369930 | M53: =H53 + I53 + K53+ L53 -> 1572250 | N53: =G53 + M53 -> 2522250 | O53: =IF( F54="with_FTA", SUMIFS( import_cost_model!L:L, import_cost_model!A:A, A54, import_cost_model!E:E, "no_FTA" ) - M54, "" )
A54: 52 | B54: 152 | C54: Volkswagen | D54: Taigun | E54: Highline | F54: no_FTA | G54: =_xlfn.XLOOKUP($B16,car_master!$B16:$B52,car_master!$I16:$I52) -> 1200000 | H54: =_xlfn.XLOOKUP(B16,car_master!$B16:$B52,car_master!$I16:$I52) * tax_parameters!$B$2 -> 840000 | I54: {=_xlfn.XLOOKUP($B54,$B$40:$B$76,$H$40:$H$76 * tax_parameters!$C$2)} -> 84000 | J54: =G54 + H54 + I54 -> 2124000 | K54: {=_xlfn.XLOOKUP($B54,$B54:$B90,$J54:$J90 * tax_parameters!$D$2)} -> 594720 | L54: {=_xlfn.XLOOKUP($B54, $B54:$B90, $J54:$J90 * 0.22)} -> 467280 | M54: =H54 + I54 + K54+ L54 -> 1986000 | N54: =G54 + M54 -> 3186000 | O54: =IF( F55="with_FTA", SUMIFS( import_cost_model!L:L, import_cost_model!A:A, A55, import_cost_model!E:E, "no_FTA" ) - M55, "" )
A55: 53 | B55: 153 | C55: Volkswagen | D55: Taigun | E55: GT Plus | F55: no_FTA | G55: =_xlfn.XLOOKUP($B17,car_master!$B17:$B53,car_master!$I17:$I53) -> 1550000 | H55: =_xlfn.XLOOKUP(B17,car_master!$B17:$B53,car_master!$I17:$I53) * tax_parameters!$B$2 -> 1085000 | I55: {=_xlfn.XLOOKUP($B55,$B$40:$B$76,$H$40:$H$76 * tax_parameters!$C$2)} -> 108500 | J55: =G55 + H55 + I55 -> 2743500 | K55: {=_xlfn.XLOOKUP($B55,$B55:$B91,$J55:$J91 * tax_parameters!$D$2)} -> 768180 | L55: {=_xlfn.XLOOKUP($B55, $B55:$B91, $J55:$J91 * 0.22)} -> 603570 | M55: =H55 + I55 + K55+ L55 -> 2565250 | N55: =G55 + M55 -> 4115250 | O55: =IF( F56="with_FTA", SUMIFS( import_cost_model!L:L, import_cost_model!A:A, A56, import_cost_model!E:E, "no_FTA" ) - M56, "" )
...
